Workbook

Sheet 시작
B1: 이 서식 파일 정보
B2: 이 템플릿을 사용하여 채널 마케팅 예산을 만드세요.
B3: 표에 월별 예상 판매량과 각종 정보를 입력하면 됩니다.
B4: 정보를 입력하면 합계가 자동으로 계산되고 스파크라인이 업데이트됩니다.
B5: 참고:
B6: 채널 마케팅 예산 워크시트의 A열에서 더 자세한 지침을 확인할 수 있습니다. 이 텍스트는 일부러 숨겨 놓았습니다. 텍스트를 제거하려면 A열을 선택한 다음 [삭제]를 선택합니다. 텍스트를 표시하려면 A열을 선택한 다음 글꼴 색상을 변경합니다.
B7: 표에 대해 자세히 알려면 표 안에서 SHIFT 키를 누른 채 F10 키를 누르고 [표] 옵션을 선택한 다음, [대체 텍스트]를 선택합니다.

Sheet 채널 마케팅 예산
A1: 이 워크시트에 채널 마케팅 예산을 작성합니다. 오른쪽 셀에 이 워크시트의 제목이 표시됩니다. 이 열의 몇몇 셀에서 유용한 지침을 확인할 수 있습니다. 아래쪽 화살표를 사용하여 시작할 수 있습니다. 오른쪽 셀에 이 워크시트의 제목이 표시됩니다.
A2: 이 행의 셀 C2:O2에는 요율 및 월 레이블이, 셀 Q2에는 합계 레이블이 있습니다. | C2: 요율 | D2: 1월 | E2: 2월 | F2: 3월 | G2: 4월 | H2: 5월 | I2: 6월 | J2: 7월 | K2: 8월 | L2: 9월 | M2: 10월 | N2: 11월 | O2: 12월 | Q2: 합계
A3: 오른쪽 셀에는 예상 판매량 합계 레이블이 있습니다. 셀 D3:O3에 월별 예상 판매량을 입력합니다. 합계는 셀 Q3에 자동 계산됩니다. | B3: 예상 판매량 합계 \(000,000) | D3: 790 | E3: 200 | F3: 500 | G3: 1500 | H3: 1200 | I3: 1500 | J3: 1500 | K3: 1800 | L3: 2000 | M3: 2000 | N3: 2000 | O3: 2000 | Q3: =SUM(D3:O3) -> 16990
A4: 오른쪽 셀에서 시작하는 인건비 표에 세부 정보를 입력합니다. 표 마지막에 인건비 월별 합계가, 셀 Q9에 연간 합계가 자동으로 계산됩니다. 셀 S9에는 스파크라인이 업데이트됩니다. 다음 지침은 A10 셀에 있습니다. | B4: 인건비 항목 | C4: 요율 | D4: 1월 | E4: 2월 | F4: 3월 | G4: 4월 | H4: 5월 | I4: 6월 | J4: 7월 | K4: 8월 | L4: 9월 | M4: 10월 | N4: 11월 | O4: 12월
B5: 인건비 (총 판매량에서 차지하는 비율) | D5: =D11+D36+D44+D51 -> 1.1 | E5: =E11+E36+E44+E51 -> 1.1 | F5: =F11+F36+F44+F51 -> 1.1 | G5: =G11+G36+G44+G51 -> 1.1 | H5: =H11+H36+H44+H51 -> 1.1 | I5: =I11+I36+I44+I51 -> 1.1 | J5: =J11+J36+J44+J51 -> 1.1 | K5: =K11+K36+K44+K51 -> 1.1 | ... O5: =O11+O36+O44+O51 -> 0.85
B6: 인사 - 인원수 | C6: 5 | D6: =+$C$6 -> 5 | E6: =+$C$6 -> 5 | F6: =+$C$6 -> 5 | G6: =+$C$6 -> 5 | H6: =+$C$6 -> 5 | I6: =+$C$6 -> 5 | J6: =+$C$6 -> 5 | K6: =+$C$6 -> 5 | ... O6: =+$C$6 -> 5
B7: 인사 - 비용 | D7: =$C$6*D6 -> 25 | E7: =$C$6*E6 -> 25 | F7: =$C$6*F6 -> 25 | G7: =$C$6*G6 -> 25 | H7: =$C$6*H6 -> 25 | I7: =$C$6*I6 -> 25 | J7: =$C$6*J6 -> 25 | K7: =$C$6*K6 -> 25 | ... O7: =$C$6*O6 -> 25 | Q7: =SUM('채널 마케팅 예산'!$D7:$O7) -> 300
B8: 수수료 | C8: 0.001 | D8: =D3*$C$8 -> 0.79 | E8: =E3*$C$8 -> 0.2 | F8: =F3*$C$8 -> 0.5 | G8: =G3*$C$8 -> 1.5 | H8: =H3*$C$8 -> 1.2 | I8: =I3*$C$8 -> 1.5 | J8: =J3*$C$8 -> 1.5 | K8: =K3*$C$8 -> 1.8 | ... O8: =O3*$C$8 -> 2 | Q8: =SUM('채널 마케팅 예산'!$D8:$O8) -> 16.99
B9: 인건비 합계 \(000,000) | D9: =SUM(D7:D8) -> 25.79 | E9: =SUM(E7:E8) -> 25.2 | F9: =SUM(F7:F8) -> 25.5 | G9: =SUM(G7:G8) -> 26.5 | H9: =SUM(H7:H8) -> 26.2 | I9: =SUM(I7:I8) -> 26.5 | J9: =SUM(J7:J8) -> 26.5 | K9: =SUM(K7:K8) -> 26.8 | ... O9: =SUM(O7:O8) -> 27 | Q9: =SUM(Q7:Q8) -> 316.99
A10: 오른쪽 셀에서 시작하는 다이렉트마케팅 표에 세부 정보를 입력합니다. 표 마지막에 텔레마케팅 월별 합계가, 셀 Q17에 연간 합계가 자동으로 계산됩니다. 셀 S17에는 스파크라인이 업데이트됩니다. 다음 지침은 셀 A18에 있습니다. | B10: 직접 마케팅 항목 | C10: 요율 | D10: 1월 | E10: 2월 | F10: 3월 | G10: 4월 | H10: 5월 | I10: 6월 | J10: 7월 | K10: 8월 | L10: 9월 | M10: 10월 | N10: 11월 | O10: 12월
B11: 직접 마케팅(총 판매량에서 차지하는 비율) | D11: 1 | E11: 1 | F11: 0.75 | G11: 0.4 | H11: 0.33 | I11: 0.25 | J11: 0.2 | K11: 0.1 | L11: 0.05 | M11: 0.05 | N11: 0.05 | O11: 0.05
B12: 텔레마케팅 (다이렉트 판매량에서 차지하는 비율) | D12: 1 | E12: 0.5 | F12: 0.5 | G12: 0.5 | H12: 0.5 | I12: 0.5 | J12: 0.5 | K12: 0.5 | L12: 0.5 | M12: 0.5 | N12: 0.5 | O12: 0.5
B13: 인사 - 인원수 | C13: 3 | D13: =$C$13*D12 -> 3 | E13: =$C$13*E12 -> 1.5 | F13: =$C$13*F12 -> 1.5 | G13: =$C$13*G12 -> 1.5 | H13: =$C$13*H12 -> 1.5 | I13: =$C$13*I12 -> 1.5 | J13: =$C$13*J12 -> 1.5 | K13: =$C$13*K12 -> 1.5 | ... O13: =$C$13*O12 -> 1.5 | Q13: =SUM('채널 마케팅 예산'!$D13:$O13) -> 19.5
B14: 인프라 지원 | D14: 25 | E14: 10 | F14: 25 | G14: 10 | H14: 25 | I14: 10 | J14: 25 | K14: 10 | L14: 25 | M14: 10 | N14: 25 | O14: 10 | Q14: =SUM('채널 마케팅 예산'!$D14:$O14) -> 210
B15: 수수료 | C15: 0.001 | D15: =$C$15*D3*D11*D12 -> 0.79 | E15: =$C$15*E3*E11*E12 -> 0.1 | F15: =$C$15*F3*F11*F12 -> 0.1875 | G15: =$C$15*G3*G11*G12 -> 0.3 | H15: =$C$15*H3*H11*H12 -> 0.198 | I15: =$C$15*I3*I11*I12 -> 0.1875 | J15: =$C$15*J3*J11*J12 -> 0.15 | K15: =$C$15*K3*K11*K12 -> 0.09 | ... O15: =$C$15*O3*O11*O12 -> 0.05 | Q15: =SUM('채널 마케팅 예산'!$D15:$O15) -> 2.203
B16: 온라인 교육 | D16: 25 | E16: 10 | F16: 25 | G16: 10 | H16: 25 | I16: 10 | J16: 25 | K16: 10 | L16: 25 | M16: 10 | N16: 25 | O16: 10 | Q16: =SUM('채널 마케팅 예산'!$D16:$O16) -> 210
B17: 텔레마케팅 합계 \(000,000) | D17: =SUM(D13:D16) -> 53.79 | E17: =SUM(E13:E16) -> 21.6 | F17: =SUM(F13:F16) -> 51.6875 | G17: =SUM(G13:G16) -> 21.8 | H17: =SUM(H13:H16) -> 51.698 | I17: =SUM(I13:I16) -> 21.6875 | J17: =SUM(J13:J16) -> 51.65 | K17: =SUM(K13:K16) -> 21.59 | ... O17: =SUM(O13:O16) -> 21.55 | Q17: =SUM(Q13:Q16) -> 441.703
A18: 오른쪽 셀에서 시작하는 인터넷 마케팅 표에 세부 정보를 입력합니다. 표 마지막에 인터넷 마케팅 월별 합계가, 셀 Q24에 연간 합계가 자동으로 계산됩니다. 셀 S24에는 스파크라인이 업데이트됩니다. 다음 지침은 A25 셀에 있습니다. | B18: 인터넷 마케팅 항목 | C18: 요율 | D18: 1월 | E18: 2월 | F18: 3월 | G18: 4월 | H18: 5월 | I18: 6월 | J18: 7월 | K18: 8월 | L18: 9월 | M18: 10월 | N18: 11월 | O18: 12월
B19: 인터넷 마케팅(다이렉트 판매량에서 차지하는 비율) | D19: 0.25 | E19: 0.25 | F19: 0.25 | G19: 0.25 | H19: 0.25 | I19: 0.25 | J19: 0.25 | K19: 0.25 | L19: 0.25 | M19: 0.25 | N19: 0.25 | O19: 0.25
B20: 인사 - 인원수 | C20: 1 | D20: =$C$20*D19 -> 0.25 | E20: =$C$20*E19 -> 0.25 | F20: =$C$20*F19 -> 0.25 | G20: =$C$20*G19 -> 0.25 | H20: =$C$20*H19 -> 0.25 | I20: =$C$20*I19 -> 0.25 | J20: =$C$20*J19 -> 0.25 | K20: =$C$20*K19 -> 0.25 | ... O20: =$C$20*O19 -> 0.25 | Q20: =SUM('채널 마케팅 예산'!$D20:$O20) -> 3
B21: 웹 사이트 개발(일회성 비용) | D21: 500 | Q21: =SUM('채널 마케팅 예산'!$D21:$O21) -> 500
B22: 호스팅 | D22: 10 | E22: 10 | F22: 10 | G22: 10 | H22: 10 | I22: 10 | J22: 10 | K22: 10 | L22: 10 | M22: 10 | N22: 10 | O22: 10 | Q22: =SUM('채널 마케팅 예산'!$D22:$O22) -> 120
B23: 지원 및 유지 관리 | D23: 25 | N23: 25 | Q23: =SUM('채널 마케팅 예산'!$D23:$O23) -> 50
B24: Facebook | E24: 100 | G24: 100 | I24: 100 | K24: 100 | M24: 100 | O24: 100 | Q24: =SUM('채널 마케팅 예산'!$D24:$O24) -> 600
B25: Twitter | D25: 100 | F25: 100 | H25: 100 | J25: 100 | L25: 100 | N25: 100 | Q25: =SUM('채널 마케팅 예산'!$D25:$O25) -> 600
B26: YouTube | E26: 100 | G26: 100 | H26: 100 | L26: 100 | M26: 100 | O26: 100 | Q26: =SUM('채널 마케팅 예산'!$D26:$O26) -> 600
B27: 인터넷 마케팅 합계 \(000,000) | D27: =SUM(D20:D23) -> 535.25 | E27: =SUM(E20:E23) -> 10.25 | F27: =SUM(F20:F23) -> 10.25 | G27: =SUM(G20:G23) -> 10.25 | H27: =SUM(H20:H23) -> 10.25 | I27: =SUM(I20:I23) -> 10.25 | J27: =SUM(J20:J23) -> 10.25 | K27: =SUM(K20:K23) -> 10.25 | ... O27: =SUM(O20:O23) -> 10.25 | Q27: =SUM(Q20:Q23) -> 673
A28: 오른쪽 셀에서 시작하는 다이렉트 메일 표에 세부 정보를 입력합니다. 표 마지막에 다이렉트 메일 월별 합계가, 셀 Q30에 연간 합계가 자동으로 계산됩니다. 다음 지침은 셀 A31에 있습니다. | B28: 다이렉트 메일 항목 | C28: 요율 | D28: 1월 | E28: 2월 | F28: 3월 | G28: 4월 | H28: 5월 | I28: 6월 | J28: 7월 | K28: 8월 | L28: 9월 | M28: 10월 | N28: 11월 | O28: 12월
B29: 다이렉트 메일(다이렉트 판매량에서 차지하는 비율)
B30: 인사 - 비용 | Q30: =SUM('채널 마케팅 예산'!$D30:$O30) -> 0
B31: 준비물 | D31: 1000 | E31: 1000 | F31: 1000 | G31: 1000 | H31: 1000 | I31: 1000 | J31: 1000 | K31: 1000 | L31: 1000 | M31: 1000 | N31: 1000 | O31: 1000 | Q31: =SUM('채널 마케팅 예산'!$D31:$O31) -> 12000
B32: 우편 | D32: 250 | E32: 250 | F32: 250 | G32: 250 | H32: 250 | I32: 250 | J32: 250 | K32: 250 | L32: 250 | M32: 250 | N32: 250 | O32: 250 | Q32: =SUM('채널 마케팅 예산'!$D32:$O32) -> 3000
B33: 다이렉트 메일 합계 \(000,000) | D33: =SUM(D30:D32) -> 1250 | E33: =SUM(E30:E32) -> 1250 | F33: =SUM(F30:F32) -> 1250 | G33: =SUM(G30:G32) -> 1250 | H33: =SUM(H30:H32) -> 1250 | I33: =SUM(I30:I32) -> 1250 | J33: =SUM(J30:J32) -> 1250 | K33: =SUM(K30:K32) -> 1250 | ... O33: =SUM(O30:O32) -> 1250 | Q33: =SUM(Q30:Q32) -> 15000
A34: 이 행의 셀 D31:O31에 다이렉트 마케팅 합계가, 셀 Q31에 연간 합계가 자동으로 계산됩니다. 셀 S31에는 스파크라인이 업데이트됩니다. | B34: 다이렉트 마케팅 합계 \(000,000) | D34: =SUM(DirectMail[[#Totals],[1월]],InternetMarketing[[#Totals],[1월]],DirectMarketing[[#Totals],[1월]]) -> 1839.04 | E34: =SUM(DirectMail[[#Totals],[2월]],InternetMarketing[[#Totals],[2월]],DirectMarketing[[#Totals],[2월]]) -> 1281.85 | F34: =SUM(DirectMail[[#Totals],[3월]],InternetMarketing[[#Totals],[3월]],DirectMarketing[[#Totals],[3월]]) -> 1311.9375 | G34: =SUM(DirectMail[[#Totals],[4월]],InternetMarketing[[#Totals],[4월]],DirectMarketing[[#Totals],[4월]]) -> 1282.05 | H34: =SUM(DirectMail[[#Totals],[5월]],InternetMarketing[[#Totals],[5월]],DirectMarketing[[#Totals],[5월]]) -> 1311.948 | I34: =SUM(DirectMail[[#Totals],[6월]],InternetMarketing[[#Totals],[6월]],DirectMarketing[[#Totals],[6월]]) -> 1281.9375 | J34: =SUM(DirectMail[[#Totals],[7월]],InternetMarketing[[#Totals],[7월]],DirectMarketing[[#Totals],[7월]]) -> 1311.9 | K34: =SUM(DirectMail[[#Totals],[8월]],InternetMarketing[[#Totals],[8월]],DirectMarketing[[#Totals],[8월]]) -> 1281.84 | L34: =SUM(DirectMail[[#Totals],[9월]],InternetMarketing[[#Totals],[9월]],DirectMarketing[[#Totals],[9월]]) -> 1311.8 | M34: =SUM(DirectMail[[#Totals],[10월]],InternetMarketing[[#Totals],[10월]],DirectMarketing[[#Totals],[10월]]) -> 1281.8 | N34: =SUM(DirectMail[[#Totals],[11월]],InternetMarketing[[#Totals],[11월]],DirectMarketing[[#Totals],[11월]]) -> 1336.8 | O34: =SUM(DirectMail[[#Totals],[12월]],InternetMarketing[[#Totals],[12월]],DirectMarketing[[#Totals],[12월]]) -> 1281.8 | Q34: =SUM(Q33,Q27,Q17,Q9) -> 16431.693
A35: 오른쪽 셀에서 시작하는 에이전트/브로커 표에 세부 정보를 입력합니다. 표 마지막에 에이전트/브로커 월별 합계가, 셀 Q39에 연간 합계가 자동으로 계산됩니다. 셀 S39에는 스파크라인이 업데이트됩니다. 다음 지침은 셀 A40에 있습니다. | B35: 에이전트/브로커 항목 | C35: 요율 | D35: 1월 | E35: 2월 | F35: 3월 | G35: 4월 | H35: 5월 | I35: 6월 | J35: 7월 | K35: 8월 | L35: 9월 | M35: 10월 | N35: 11월 | O35: 12월
B36: 에이전트/브로커(총 판매량에서 차지하는 비율) | D36: 0.1 | E36: 0.1 | F36: 0.1 | G36: 0.1 | H36: 0.1 | I36: 0.1 | J36: 0.1 | K36: 0.1 | L36: 0.1 | M36: 0.1 | N36: 0.1 | O36: 0.1
B37: 의사소통 | D37: 50 | E37: 50 | F37: 50 | G37: 50 | H37: 50 | I37: 50 | J37: 50 | K37: 50 | L37: 50 | M37: 50 | N37: 50 | O37: 50 | Q37: =SUM('채널 마케팅 예산'!$D37:$O37) -> 600
B38: 온라인 교육 | D38: 250 | E38: 250 | F38: 250 | G38: 250 | H38: 250 | I38: 250 | J38: 250 | K38: 250 | L38: 250 | M38: 250 | N38: 250 | O38: 250 | Q38: =SUM('채널 마케팅 예산'!$D38:$O38) -> 3000
B39: 판촉 | D39: 600 | E39: 600 | F39: 600 | G39: 600 | H39: 600 | I39: 600 | J39: 600 | K39: 600 | L39: 600 | M39: 600 | N39: 600 | O39: 600 | Q39: =SUM('채널 마케팅 예산'!$D39:$O39) -> 7200
B40: 할인 | C40: 0.1 | D40: =D3*D36*$C$40 -> 7.9 | E40: =E3*E36*$C$40 -> 2 | F40: =F3*F36*$C$40 -> 5 | G40: =G3*G36*$C$40 -> 15 | H40: =H3*H36*$C$40 -> 12 | I40: =I3*I36*$C$40 -> 15 | J40: =J3*J36*$C$40 -> 15 | K40: =K3*K36*$C$40 -> 18 | ... O40: =O3*O36*$C$40 -> 20 | Q40: =SUM('채널 마케팅 예산'!$D40:$O40) -> 169.9
...
